Workbook
Name AliqImp: #REF!
Name Capex: #REF!
Name CPV: #REF!
Name Cresc: '[1]Fluxo de Caixa A-1'!$D$13
Name CtasPagar: #REF!
Name CtasReceber: #REF!
Name CxOperac: #REF!
Name Depreciacao: #REF!
Name DespGeraisAdm: #REF!
Name elast: #REF!
Name Estoque: #REF!
Name ImpComp: #REF!
Name ImpPagar: #REF!
Name InvCGL: #REF!
Name Objetivos: INDIRECT("Auxiliar_Slides!$C$303:$S$"&305+MAX(COUNTIF([2]Auxiliar_Slides!$F$305:$F$326,">"&0),COUNTIF([2]Auxiliar_Slides!$R$305:$R$326,">"&0)))
Name ppa: #REF!
Name ReceitaLiquida: #REF!
Name ResOperac: #REF!
Name SalEncPagar: #REF!
Name SegmentaçãodeDados_Centro_de_custos: #N/A
Name SegmentaçãodeDados_Centro_de_custos1: #N/A
Name SegmentaçãodeDados_Centro_de_custos2: #N/A
Name SegmentaçãodeDados_Empresa: #N/A
Name SegmentaçãodeDados_Empresa1: #N/A
Name SegmentaçãodeDados_Empresa2: #N/A
Name WACC: '[1]Fluxo de Caixa A-1'!$D$22
Name WACCBR: [1]WACC!$C$10

Sheet CNS
A2: AuM | B2: =Consolidated!E4 -> 290504767 | C2: =Consolidated!F4 -> 304511145 | D2: =Consolidated!G4 -> 309415143 | E2: =Consolidated!H4 -> 311856596 | F2: =Consolidated!I4 -> 312069591 | G2: =Consolidated!J4 -> 295791970 | H2: =Consolidated!K4 -> 254401486 | I2: =Consolidated!L4 -> 0 | ... M2: =Consolidated!P4 -> 0
A3: ROA m | B3: =IF(B9>0,B9/B2,0) -> 0.00060518525 | C3: =IF(C9>0,C9/C2,0) -> 0.00058541463 | D3: =IF(D9>0,D9/D2,0) -> 0.00059200574 | E3: =IF(E9>0,E9/E2,0) -> 0.00061552272 | F3: =IF(F9>0,F9/F2,0) -> 0.00061657497 | G3: =IF(G9>0,G9/G2,0) -> 0.00063406671 | H3: =IF(H9>0,H9/H2,0) -> 0.00068929086 | I3: =IF(I9>0,I9/I2,0) -> 0 | ... M3: =IF(M9>0,M9/M2,0) -> 0
A4: Roa A | B4: =IF(B3<>0,(1+B3)^(12/1)-1,"") -> 0.0072864443 | C4: =IF(C3<>0,(1+C3)^(12/1)-1,"") -> 0.0070476387 | D4: =IF(D3<>0,(1+D3)^(12/1)-1,"") -> 0.0071272456 | E4: =IF(E3<>0,(1+E3)^(12/1)-1,"") -> 0.0074113293 | F4: =IF(F3<>0,(1+F3)^(12/1)-1,"") -> 0.0074240422 | G4: =IF(G3<>0,(1+G3)^(12/1)-1,"") -> 0.0076353913 | H4: =IF(H3<>0,(1+H3)^(12/1)-1,"") -> 0.0083029206 | I4: =IF(I3<>0,(1+I3)^(12/1)-1,"") | ... M4: =IF(M3<>0,(1+M3)^(12/1)-1,"")
A6: DRE | B6: Mês da baixa
A7: Categoria | B7: Jan/2026 | C7: Fev/2026 | D7: Mar/2026 | E7: Abr/2026 | F7: 46143 | G7: 46174 | H7: 46204 | I7: 46235 | J7: 46266 | K7: 46296 | L7: 46327 | M7: 46357 | N7: Total
A8: 01 Receitas Operacionais | B8: 239855.2 | C8: 250631.14 | D8: 228175.54 | E8: 230080.36 | F8: 232914.3 | G8: 277490.46 | H8: 227626.62 | N8: =SUM(B8:M8) -> 1686773.6
A9: 01.1 Consultoria | B9: 175809.2 | C9: 178265.28 | D9: 183175.54 | E9: 191954.82 | F9: 192414.3 | G9: 187551.84 | H9: 175356.62 | N9: =SUM(B9:M9) -> 1284527.6
A10: 01.2 Planejamento | B10: 14700 | C10: 18900 | D10: 10400 | E10: 6500 | F10: 6500 | G10: 0,00 | H10: 18270 | N10: =SUM(B10:M10) -> 75270
A11: 01.3 Tesouro Mato Grosso | B11: 34000 | C11: 34000 | D11: 34000 | E11: 0,00 | F11: 34000 | G11: 83700 | H11: 34000 | N11: =SUM(B11:M11) -> 253700
A12: 01.4 RPPS | B12: 15346 | C12: 18715.86 | D12: 0,00 | E12: 30425.54 | F12: 0,00 | G12: 6238.62 | H12: 0,00 | N12: =SUM(B12:M12) -> 70726.02
A13: 01.5 Consulta | B13: 0,00 | C13: 750 | D13: 600 | E13: 1200 | F13: 0,00 | G13: 0,00 | H13: 0,00 | N13: =SUM(B13:M13) -> 2550
A14: 01.6 Valuation | B14: 0 | C14: 0,00 | D14: 0,00 | E14: 0,00 | F14: 0,00 | G14: 0,00 | H14: 0,00 | N14: =SUM(B14:M14) -> 0
A15: 01T Receita Bruta de Vendas | B15: 239855.2 | C15: 250631.14 | D15: 228175.54 | E15: 230080.36 | F15: 232914.3 | G15: 277490.46 | H15: 227626.62 | N15: =SUM(B15:M15) -> 1686773.6
A16: 02 Deduções da Receita Bruta | B16: -177743.88 | C16: -108921.69 | D16: -121072.98 | E16: -170232.02 | F16: -110761.27 | G16: -111550.61 | H16: -175776.84 | N16: =SUM(B16:M16) -> -976059.29
A17: 02.1 Impostos Sobre Vendas | B17: -93125.38 | C17: -22147.37 | D17: -24947.44 | E17: -81040.13 | F17: -20948.04 | G17: -23544.72 | H17: -96739.75 | N17: =SUM(B17:M17) -> -362492.83 | O17: =N17/N8 -> -0.21490307
A18: 02.2 Comissões Consultores | B18: -78563.01 | C18: -78042.82 | D18: -86512.28 | E18: -81040.02 | F18: -80187.14 | G18: -81460.06 | H18: -72271.88 | N18: =SUM(B18:M18) -> -558077.21
A19: 02.3 Comissões Mesa | B19: -5749.27 | C19: -5695.28 | D19: -7461.4 | E19: -5965.22 | F19: -8479.87 | G19: -6239.61 | H19: -6458.99 | N19: =SUM(B19:M19) -> -46049.64
A20: 02.4 Descontos Incondicionais | B20: 0,00 | C20: -2730 | D20: -420 | E20: -1880.43 | F20: -840 | G20: 0,00 | H20: 0,00 | N20: =SUM(B20:M20) -> -5870.43
A21: 02.5 Devoluções de Vendas | B21: 0,00 | C21: 0,00 | D21: -1425.64 | E21: 0,00 | F21: 0,00 | G21: 0,00 | H21: 0,00 | N21: =SUM(B21:M21) -> -1425.64
A22: 02.6 Comissões Parceiros | B22: -306.22 | C22: -306.22 | D22: -306.22 | E22: -306.22 | F22: -306.22 | G22: -306.22 | H22: -306.22 | N22: =SUM(B22:M22) -> -2143.54
A23: 02T Receita Líquida de Vendas | B23: 62111.32 | C23: 141709.45 | D23: 107102.56 | E23: 59848.34 | F23: 122153.03 | G23: 165939.85 | H23: 51849.78 | N23: =SUM(B23:M23) -> 710714.33
A24: 03 Custos Operacionais | B24: -45973.64 | C24: -39048.45 | D24: -52448.17 | E24: -47406.54 | F24: -60020.04 | G24: -47468.03 | H24: -43406.91 | N24: =SUM(B24:M24) -> -335771.78
A25: 03.1 Salários e Encargos | B25: -6659.05 | C25: -10429.4 | D25: -13062.59 | E25: -11040.54 | F25: -11647.38 | G25: -15156.07 | H25: -11933.16 | N25: =SUM(B25:M25) -> -79928.19
A26: 03.2 Sistemas | B26: -15303.94 | C26: -9519.05 | D26: -13097.35 | E26: -10678.38 | F26: -9918.7 | G26: -9939.96 | H26: -10299.93 | N26: =SUM(B26:M26) -> -78757.31
A27: 03.3 Custo Tesouro mato grosso | B27: -21367.88 | C27: -19100 | D27: -26235.23 | E27: -25581.62 | F27: -32735.46 | G27: -22372 | H27: -21173.82 | N27: =SUM(B27:M27) -> -168566.01
A28: 03.4 Custo RPPS | B28: -1119.18 | C28: 0,00 | D28: 0,00 | E28: 0,00 | F28: 0,00 | G28: 0,00 | H28: 0,00 | N28: =SUM(B28:M28) -> -1119.18
A29: 03.5 Regulatórias | B29: -1523.59 | C29: 0,00 | D29: -53 | E29: -106 | F29: -5718.5 | G29: 0 | H29: 0 | N29: =SUM(B29:M29) -> -7401.09
A30: 03T Lucro Bruto | B30: 16137.68 | C30: 102661 | D30: 54654.39 | E30: 12441.8 | F30: 62132.99 | G30: 118471.82 | H30: 8442.87 | N30: =SUM(B30:M30) -> 374942.55
A31: 04 Despesas Operacionais | B31: -22722.73 | C31: -22213.48 | D31: -23785.24 | E31: -20323.96 | F31: -19904.76 | G31: -19438.82 | H31: -29716.58 | N31: =SUM(B31:M31) -> -158105.57
A32: 04.1 Imóvel | B32: -10767.65 | C32: -7850.3 | D32: -8253.59 | E32: -8252.46 | F32: -9165.58 | G32: -8964.05 | H32: -8776.49 | N32: =SUM(B32:M32) -> -62030.12
A33: 04.10 Outras Despesas | B33: 0 | C33: 0,00 | D33: 0,00 | E33: 0,00 | F33: 0,00 | G33: 0,00 | H33: 0,00 | N33: =SUM(B33:M33) -> 0
A34: 04.2 Serviços | B34: -4432.61 | C34: -4617.94 | D34: -4617.94 | E34: -4617.94 | F34: -4617.94 | G34: -4617.94 | H34: -13617.94 | N34: =SUM(B34:M34) -> -41140.25
A35: 04.3 Comerciais | B35: -2598.88 | C35: -3044.37 | D35: -4764.36 | E35: -2982.44 | F35: -1595.19 | G35: -484.9 | H35: -195 | N35: =SUM(B35:M35) -> -15665.14
A36: 04.4 Administrativas | B36: -2058.78 | C36: -3995.84 | D36: -3193.74 | E36: -2495.51 | F36: -2050.44 | G36: -3396.32 | H36: -3290.59 | N36: =SUM(B36:M36) -> -20481.22
A37: 04.5 Colaboradores | B37: -1957.95 | C37: -1798.17 | D37: -2048.75 | E37: -1068.75 | F37: -1568.75 | G37: -1068.75 | H37: -2929.7 | N37: =SUM(B37:M37) -> -12440.82
A38: 04.6 Diretoria | B38: -906.86 | C38: -906.86 | D38: -906.86 | E38: -906.86 | F38: -906.86 | G38: -906.86 | H38: -906.86 | N38: =SUM(B38:M38) -> -6348.02
A39: 04.7 Imobilizados e equipamentos | B39: 0 | C39: 0,00 | D39: 0,00 | E39: 0,00 | F39: 0,00 | G39: 0,00 | H39: 0,00 | N39: =SUM(B39:M39) -> 0
A40: 04.8 Vendas | B40: 0 | C40: 0,00 | D40: 0,00 | E40: 0,00 | F40: 0,00 | G40: 0,00 | H40: 0,00 | N40: =SUM(B40:M40) -> 0
A41: 04.9 Veículos | B41: 0 | C41: 0,00 | D41: 0,00 | E41: 0,00 | F41: 0,00 | G41: 0,00 | H41: 0,00 | N41: =SUM(B41:M41) -> 0
A42: 04T Lucro / Prejuízo Operacional | B42: -6585.05 | C42: 80447.52 | D42: 30869.15 | E42: -7882.16 | F42: 42228.23 | G42: 99033 | H42: -21273.71 | N42: =SUM(B42:M42) -> 216836.98
...

Sheet CRR
A2: AuM | B2: =Consolidated!E4 -> 290504767 | C2: =Consolidated!F4 -> 304511145 | D2: =Consolidated!G4 -> 309415143 | E2: =Consolidated!H4 -> 311856596 | F2: =Consolidated!I4 -> 312069591 | G2: =Consolidated!J4 -> 295791970 | H2: =Consolidated!K4 -> 254401486 | I2: =Consolidated!L4 -> 0 | ... M2: =Consolidated!P4 -> 0
A6: DRE | B6: Mês da baixa
A7: Categoria | B7: Jan/2026 | C7: Fev/2026 | D7: Mar/2026 | E7: Abr/2026 | F7: 46143 | G7: 46174 | H7: 46204 | I7: 46235 | J7: 46266 | K7: 46296 | L7: 46327 | M7: 46357 | N7: Total
A8: 01 Receitas Operacionais | B8: 42588.73 | C8: 34365.1 | D8: 44620.81 | E8: 36640.27 | F8: 44420.28 | G8: 24067.41 | H8: 52992.46 | N8: =SUM(B8:M8) -> 279695.06
A9: 01.1 Câmbio/Bancários | B9: 2129.24 | C9: 4080.01 | D9: 7882.59 | E9: 3358.51 | F9: 4335.02 | G9: 0,00 | H9: 5592.59 | N9: =SUM(B9:M9) -> 27377.96
A10: 01.2 Consórcio | B10: 11277.6 | C10: 11277.6 | D10: 11277.6 | E10: 11277.6 | F10: 11277.6 | G10: 0,00 | H10: 17767.2 | N10: =SUM(B10:M10) -> 74155.2
A11: 01.3 Previdência | B11: 4958.36 | C11: 4860.28 | D11: 6325.28 | E11: 5913.91 | F11: 2187.12 | G11: 3486.48 | H11: 3208.11 | N11: =SUM(B11:M11) -> 30939.54
A12: 01.4 Seguro de vida | B12: 20365.39 | C12: 11096.95 | D12: 13782.61 | E12: 11693.06 | F12: 19858.71 | G12: 16176.26 | H12: 19179.52 | N12: =SUM(B12:M12) -> 112152.5
A13: 01.5 Outros | B13: 3858.14 | C13: 3050.26 | D13: 5352.73 | E13: 4397.19 | F13: 6761.83 | G13: 4404.67 | H13: 7245.04 | N13: =SUM(B13:M13) -> 35069.86
A14: 01T Receita Bruta de Vendas | B14: 42588.73 | C14: 34365.1 | D14: 44620.81 | E14: 36640.27 | F14: 44420.28 | G14: 24067.41 | H14: 52992.46 | N14: =SUM(B14:M14) -> 279695.06
A15: 02 Deduções da Receita Bruta | B15: -21072.77 | C15: -17399.4 | D15: -17108.46 | E15: -26182.42 | F15: -17964.84 | G15: -16506.11 | H15: -19508.79 | N15: =SUM(B15:M15) -> -135742.79
A16: 02.1 Impostos Sobre Vendas | B16: -8389.22 | C16: -1884.97 | D16: -2397 | E16: -8842.03 | F16: -2316.2 | G16: -1629.85 | H16: -11875.59 | N16: =SUM(B16:M16) -> -37334.86
A17: 02.2 Comissões Consultores | B17: -10887.62 | C17: -13833.49 | D17: -11755.75 | E17: -14623.74 | F17: -11725.19 | G17: -13404.29 | H17: -5997.6 | N17: =SUM(B17:M17) -> -82227.68
A18: 02.3 Comissões Mesa | B18: 0 | C18: 0,00 | D18: 0,00 | E18: 0,00 | F18: 0,00 | G18: 0,00 | H18: 0,00 | N18: =SUM(B18:M18) -> 0
A19: 02.4 Descontos Incondicionais | B19: 0 | C19: 0,00 | D19: 0,00 | E19: 0,00 | F19: 0,00 | G19: 0,00 | H19: 0,00 | N19: =SUM(B19:M19) -> 0
A20: 02.5 Devoluções de Vendas | B20: -1163.72 | C20: -1319.61 | D20: -2497.98 | E20: -1950.63 | F20: -3298.79 | G20: -1471.97 | H20: -55.4 | N20: =SUM(B20:M20) -> -11758.1
A21: 02.6 Comissões Parceiros | B21: -632.21 | C21: -361.33 | D21: -457.73 | E21: -766.02 | F21: -624.66 | G21: 0 | H21: -1580.2 | N21: =SUM(B21:M21) -> -4422.15
A22: 02T Receita Líquida de Vendas | B22: 21515.96 | C22: 16965.7 | D22: 27512.35 | E22: 10457.85 | F22: 26455.44 | G22: 7561.3 | H22: 33483.67 | N22: =SUM(B22:M22) -> 143952.27
A23: 03 Custos Operacionais | B23: -18986.62 | C23: -22249.18 | D23: -15494.05 | E23: -17168.59 | F23: -21352.85 | G23: -19144.68 | H23: -16275.98 | N23: =SUM(B23:M23) -> -130671.95
A24: 03.1 Salários e Encargos | B24: -18767.1 | C24: -22249.18 | D24: -15494.05 | E24: -17168.59 | F24: -21352.85 | G24: -19144.68 | H24: -16275.98 | N24: =SUM(B24:M24) -> -130452.43
A25: 03.2 Sistemas | B25: -219.52 | C25: 0,00 | D25: 0,00 | E25: 0,00 | F25: 0,00 | G25: 0,00 | H25: 0,00 | N25: =SUM(B25:M25) -> -219.52
A26: 03.3 Custo Tesouro mato grosso | B26: 0 | C26: 0,00 | D26: 0,00 | E26: 0,00 | F26: 0,00 | G26: 0,00 | H26: 0,00 | N26: =SUM(B26:M26) -> 0
A27: 03.4 Custo RPPS | B27: 0 | C27: 0,00 | D27: 0,00 | E27: 0,00 | F27: 0,00 | G27: 0,00 | H27: 0,00 | N27: =SUM(B27:M27) -> 0
A28: 03.5 Regulatórias | B28: 0 | C28: 0,00 | D28: 0,00 | E28: 0,00 | F28: 0,00 | G28: 0,00 | H28: 0,00 | N28: =SUM(B28:M28) -> 0
A29: 03T Lucro Bruto | B29: 2529.34 | C29: -5283.48 | D29: 12018.3 | E29: -6710.74 | F29: 5102.59 | G29: -11583.38 | H29: 17207.69 | N29: =SUM(B29:M29) -> 13280.32
A30: 04 Despesas Operacionais | B30: -758.77 | C30: -1958.77 | D30: -851.16 | E30: -807.81 | F30: -787.76 | G30: -829.74 | H30: -656.45 | N30: =SUM(B30:M30) -> -6650.46
A31: 04.1 Imóvel | B31: 0 | C31: 0,00 | D31: 0,00 | E31: 0,00 | F31: 0,00 | G31: 0,00 | H31: 0,00 | N31: =SUM(B31:M31) -> 0
A32: 04.10 Outras Despesas | B32: 0 | C32: 0,00 | D32: 0,00 | E32: 0,00 | F32: 0,00 | G32: 0,00 | H32: 0,00 | N32: =SUM(B32:M32) -> 0
A33: 04.2 Serviços | B33: 0 | C33: 0,00 | D33: 0,00 | E33: 0,00 | F33: 0,00 | G33: 0,00 | H33: 0,00 | N33: =SUM(B33:M33) -> 0
A34: 04.3 Comerciais | B34: 0,00 | C34: -1200 | D34: -63.4 | E34: -20.05 | F34: 0,00 | G34: 0,00 | H34: 0,00 | N34: =SUM(B34:M34) -> -1283.45
A35: 04.4 Administrativas | B35: 0,00 | C35: 0,00 | D35: 0,00 | E35: 0,00 | F35: 0,00 | G35: -476.1 | H35: -72 | N35: =SUM(B35:M35) -> -548.1
A36: 04.5 Colaboradores | B36: -758.77 | C36: -758.77 | D36: -787.76 | E36: -787.76 | F36: -787.76 | G36: -353.64 | H36: -584.45 | N36: =SUM(B36:M36) -> -4818.91
A37: 04.6 Diretoria | B37: 0 | C37: 0,00 | D37: 0,00 | E37: 0,00 | F37: 0,00 | G37: 0,00 | H37: 0,00 | N37: =SUM(B37:M37) -> 0
A38: 04.7 Imobilizados e equipamentos | B38: 0 | C38: 0,00 | D38: 0,00 | E38: 0,00 | F38: 0,00 | G38: 0,00 | H38: 0,00 | N38: =SUM(B38:M38) -> 0
A39: 04.8 Vendas | B39: 0 | C39: 0,00 | D39: 0,00 | E39: 0,00 | F39: 0,00 | G39: 0,00 | H39: 0,00 | N39: =SUM(B39:M39) -> 0
A40: 04.9 Veículos | B40: 0 | C40: 0,00 | D40: 0,00 | E40: 0,00 | F40: 0,00 | G40: 0,00 | H40: 0,00 | N40: =SUM(B40:M40) -> 0
A41: 04T Lucro / Prejuízo Operacional | B41: 1770.57 | C41: -7242.25 | D41: 11167.14 | E41: -7518.55 | F41: 4314.83 | G41: -12413.12 | H41: 16551.24 | N41: =SUM(B41:M41) -> 6629.86
A42: 05 Receitas e Despesas Financeiras | B42: -6.29 | C42: 0,00 | D42: 0,00 | E42: 0,00 | F42: 0,00 | G42: -13.47 | H42: 0,00 | N42: =SUM(B42:M42) -> -19.76
A43: 06 Outras Receitas e Despesas Não Operacionais | B43: 0 | C43: 0,00 | D43: 0,00 | E43: 0,00 | F43: 0,00 | G43: 0,00 | H43: 0,00 | N43: =SUM(B43:M43) -> 0
A44: 06T Lucro / Prejuízo Líquido | B44: 1764.28 | C44: -7242.25 | D44: 11167.14 | E44: -7518.55 | F44: 4314.83 | G44: -12426.59 | H44: 16551.24 | N44: =SUM(B44:M44) -> 6610.1
...

Sheet Consolidated
D2: Aum/1k | E2: =IF(E4>0,E4/1000,0) -> 290504.77 | F2: =IF(F4>0,F4/1000,0) -> 304511.15 | G2: =IF(G4>0,G4/1000,0) -> 309415.14 | H2: =IF(H4>0,H4/1000,0) -> 311856.6 | I2: =IF(I4>0,I4/1000,0) -> 312069.59 | J2: =IF(J4>0,J4/1000,0) -> 295791.97 | K2: =IF(K4>0,K4/1000,0) -> 254401.49 | L2: =IF(L4>0,L4/1000,0) -> 0 | ... P2: =IF(P4>0,P4/1000,0) -> 0
D4: AuM | E4: =AuM!C76 -> 290504767 | F4: =AuM!C77 -> 304511145 | G4: =AuM!C78 -> 309415143 | H4: =AuM!C79 -> 311856596 | I4: =AuM!C80 -> 312069591 | J4: =AuM!C81 -> 295791970 | K4: =AuM!C82 -> 254401486 | Q4: Média | U4: Média
D5: ROA Anualizado | E5: =IF(E4>0,(E7/E4)*12,"") -> 0.011667028 | F5: =IF(F4>0,(F7/F4)*12,"") -> 0.011230968 | G5: =IF(G4>0,(G7/G4)*12,"") -> 0.010579819 | H5: =IF(H4>0,(H7/H4)*12,"") -> 0.010263203 | I5: =IF(I4>0,(I7/I4)*12,"") -> 0.010664336 | J5: =IF(J4>0,(J7/J4)*12,"") -> 0.012233917 | K5: =IF(K4>0,(K7/K4)*12,"") -> 0.013236672 | L5: =IF(L4>0,(L7/L4)*12,"") | ... P5: =IF(P4>0,(P7/P4)*12,"") | Q5: =AVERAGE(E5:P5) -> 0.011410849 | U5: 7
D6: Categoria | E6: Jan/2026 | F6: Fev/2026 | G6: Mar/2026 | H6: Abr/2026 | I6: 46143 | J6: 46174 | K6: 46204 | L6: 46235 | M6: 46266 | N6: 46296 | O6: 46327 | P6: 46357 | Q6: Total | U6: Total
D7: 01 Receitas Operacionais | E7: =CNS!B8+CRR!B8 -> 282443.93 | F7: =CNS!C8+CRR!C8 -> 284996.24 | G7: =CNS!D8+CRR!D8 -> 272796.35 | H7: =CNS!E8+CRR!E8 -> 266720.63 | I7: =CNS!F8+CRR!F8 -> 277334.58 | J7: =CNS!G8+CRR!G8 -> 301557.87 | K7: =CNS!H8+CRR!H8 -> 280619.08 | L7: =CNS!I8+CRR!I8 -> 0 | ... P7: =CNS!M8+CRR!M8 -> 0 | Q7: =SUM(E7:P7) -> 1966468.7 | T7: 01 Receitas Operacionais | U7: =Q7/$U$5 -> 280924.1
D8: Consultoria | E8: =CNS!B9 -> 175809.2 | F8: =CNS!C9 -> 178265.28 | G8: =CNS!D9 -> 183175.54 | H8: =CNS!E9 -> 191954.82 | I8: =CNS!F9 -> 192414.3 | J8: =CNS!G9 -> 187551.84 | K8: =CNS!H9 -> 175356.62 | L8: =CNS!I9 -> 0 | ... P8: =CNS!M9 -> 0 | Q8: =SUM(E8:P8) -> 1284527.6 | R8: =Q8/$Q$7 -> 0.65321539 | T8: Consultoria | U8: =Q8/$U$5 -> 183503.94
D9: Planejamento | E9: =CNS!B10 -> 14700 | F9: =CNS!C10 -> 18900 | G9: =CNS!D10 -> 10400 | H9: =CNS!E10 -> 6500 | I9: =CNS!F10 -> 6500 | J9: =CNS!G10 -> 0,00 | K9: =CNS!H10 -> 18270 | L9: =CNS!I10 -> 0 | ... P9: =CNS!M10 -> 0 | Q9: =SUM(E9:P9) -> 75270 | R9: =Q9/$Q$7 -> 0.038276735 | T9: Planejamento | U9: =Q9/$U$5 -> 10752.857
D10: Tesouro Mato Grosso | E10: =CNS!B11 -> 34000 | F10: =CNS!C11 -> 34000 | G10: =CNS!D11 -> 34000 | H10: =CNS!E11 -> 0,00 | I10: =CNS!F11 -> 34000 | J10: =CNS!G11 -> 83700 | K10: =CNS!H11 -> 34000 | L10: =CNS!I11 -> 0 | ... P10: =CNS!M11 -> 0 | Q10: =SUM(E10:P10) -> 253700 | R10: =Q10/$Q$7 -> 0.12901299 | T10: Tesouro Mato Grosso | U10: =Q10/$U$5 -> 36242.857
D11: RPPS | E11: =CNS!B12 -> 15346 | F11: =CNS!C12 -> 18715.86 | G11: =CNS!D12 -> 0,00 | H11: =CNS!E12 -> 30425.54 | I11: =CNS!F12 -> 0,00 | J11: =CNS!G12 -> 6238.62 | K11: =CNS!H12 -> 0,00 | L11: =CNS!I12 -> 0 | ... P11: =CNS!M12 -> 0 | Q11: =SUM(E11:P11) -> 70726.02 | R11: =Q11/$Q$7 -> 0.035966004 | T11: RPPS | U11: =Q11/$U$5 -> 10103.717
D12: Consulta | E12: =CNS!B13 -> 0,00 | F12: =CNS!C13 -> 750 | G12: =CNS!D13 -> 600 | H12: =CNS!E13 -> 1200 | I12: =CNS!F13 -> 0,00 | J12: =CNS!G13 -> 0,00 | K12: =CNS!H13 -> 0,00 | L12: =CNS!I13 -> 0 | ... P12: =CNS!M13 -> 0 | Q12: =SUM(E12:P12) -> 2550 | R12: =Q12/$Q$7 -> 0.0012967407 | T12: Consulta | U12: =Q12/$U$5 -> 364.28571
D13: Valuation | E13: =CNS!B14 -> 0 | F13: =CNS!C14 -> 0,00 | G13: =CNS!D14 -> 0,00 | H13: =CNS!E14 -> 0,00 | I13: =CNS!F14 -> 0,00 | J13: =CNS!G14 -> 0,00 | K13: =CNS!H14 -> 0,00 | L13: =CNS!I14 -> 0 | ... P13: =CNS!M14 -> 0 | Q13: =SUM(E13:P13) -> 0 | R13: =Q13/$Q$7 -> 0 | T13: Valuation | U13: =Q13/$U$5 -> 0
D14: Câmbio/Bancários | E14: =CRR!B9 -> 2129.24 | F14: =CRR!C9 -> 4080.01 | G14: =CRR!D9 -> 7882.59 | H14: =CRR!E9 -> 3358.51 | I14: =CRR!F9 -> 4335.02 | J14: =CRR!G9 -> 0,00 | K14: =CRR!H9 -> 5592.59 | L14: =CRR!I9 -> 0 | ... P14: =CRR!M9 -> 0 | Q14: =SUM(E14:P14) -> 27377.96 | R14: =Q14/$Q$7 -> 0.013922398 | T14: Câmbio/Bancários | U14: =Q14/$U$5 -> 3911.1371
D15: Consórcio | E15: =CRR!B10 -> 11277.6 | F15: =CRR!C10 -> 11277.6 | G15: =CRR!D10 -> 11277.6 | H15: =CRR!E10 -> 11277.6 | I15: =CRR!F10 -> 11277.6 | J15: =CRR!G10 -> 0,00 | K15: =CRR!H10 -> 17767.2 | L15: =CRR!I10 -> 0 | ... P15: =CRR!M10 -> 0 | Q15: =SUM(E15:P15) -> 74155.2 | R15: =Q15/$Q$7 -> 0.03770983 | T15: Consórcio | U15: =Q15/$U$5 -> 10593.6
D16: Previdência | E16: =CRR!B11 -> 4958.36 | F16: =CRR!C11 -> 4860.28 | G16: =CRR!D11 -> 6325.28 | H16: =CRR!E11 -> 5913.91 | I16: =CRR!F11 -> 2187.12 | J16: =CRR!G11 -> 3486.48 | K16: =CRR!H11 -> 3208.11 | L16: =CRR!I11 -> 0 | ... P16: =CRR!M11 -> 0 | Q16: =SUM(E16:P16) -> 30939.54 | R16: =Q16/$Q$7 -> 0.015733553 | T16: Previdência | U16: =Q16/$U$5 -> 4419.9343
D17: Seguro de vida | E17: =CRR!B12 -> 20365.39 | F17: =CRR!C12 -> 11096.95 | G17: =CRR!D12 -> 13782.61 | H17: =CRR!E12 -> 11693.06 | I17: =CRR!F12 -> 19858.71 | J17: =CRR!G12 -> 16176.26 | K17: =CRR!H12 -> 19179.52 | L17: =CRR!I12 -> 0 | ... P17: =CRR!M12 -> 0 | Q17: =SUM(E17:P17) -> 112152.5 | R17: =Q17/$Q$7 -> 0.057032436 | T17: Seguro de vida | U17: =Q17/$U$5 -> 16021.786
D18: Outros Ramos | E18: =CRR!B13 -> 3858.14 | F18: =CRR!C13 -> 3050.26 | G18: =CRR!D13 -> 5352.73 | H18: =CRR!E13 -> 4397.19 | I18: =CRR!F13 -> 6761.83 | J18: =CRR!G13 -> 4404.67 | K18: =CRR!H13 -> 7245.04 | L18: =CRR!I13 -> 0 | ... P18: =CRR!M13 -> 0 | Q18: =SUM(E18:P18) -> 35069.86 | R18: =Q18/$Q$7 -> 0.017833928 | T18: Outros Ramos | U18: =Q18/$U$5 -> 5009.98
D19: 01T Receita Bruta de Vendas | Q19: =SUM(E19:P19) -> 0 | R19: =Q19/$Q$7 -> 0 | T19: 01T Receita Bruta de Vendas | U19: =Q19/$U$5 -> 0
D20: 02 Deduções da Receita Bruta | E20: =CNS!B16+CRR!B15 -> -198816.65 | F20: =CNS!C16+CRR!C15 -> -126321.09 | G20: =CNS!D16+CRR!D15 -> -138181.44 | H20: =CNS!E16+CRR!E15 -> -196414.44 | I20: =CNS!F16+CRR!F15 -> -128726.11 | J20: =CNS!G16+CRR!G15 -> -128056.72 | K20: =CNS!H16+CRR!H15 -> -195285.63 | L20: =CNS!I16+CRR!I15 -> 0 | ... P20: =CNS!M16+CRR!M15 -> 0 | Q20: =SUM(E20:P20) -> -1111802.1 | R20: =Q20/$Q$7 -> -0.56538001 | T20: 02 Deduções da Receita Bruta | U20: =Q20/$U$5 -> -158828.87
D21: 02.1 Impostos Sobre Vendas | E21: =CNS!B17+CRR!B16 -> -101514.6 | F21: =CNS!C17+CRR!C16 -> -24032.34 | G21: =CNS!D17+CRR!D16 -> -27344.44 | H21: =CNS!E17+CRR!E16 -> -89882.16 | I21: =CNS!F17+CRR!F16 -> -23264.24 | J21: =CNS!G17+CRR!G16 -> -25174.57 | K21: =CNS!H17+CRR!H16 -> -108615.34 | L21: =CNS!I17+CRR!I16 -> 0 | ... P21: =CNS!M17+CRR!M16 -> 0 | Q21: =SUM(E21:P21) -> -399827.69 | R21: =Q21/$Q$7 -> -0.20332268 | T21: 02.1 Impostos Sobre Vendas | U21: =Q21/$U$5 -> -57118.241
D22: 02.2 Comissões Consultores | E22: =CNS!B18+CRR!B17 -> -89450.63 | F22: =CNS!C18+CRR!C17 -> -91876.31 | G22: =CNS!D18+CRR!D17 -> -98268.03 | H22: =CNS!E18+CRR!E17 -> -95663.76 | I22: =CNS!F18+CRR!F17 -> -91912.33 | J22: =CNS!G18+CRR!G17 -> -94864.35 | K22: =CNS!H18+CRR!H17 -> -78269.48 | L22: =CNS!I18+CRR!I17 -> 0 | ... P22: =CNS!M18+CRR!M17 -> 0 | Q22: =SUM(E22:P22) -> -640304.89 | R22: =Q22/$Q$7 -> -0.32561154 | T22: 02.2 Comissões Consultores | U22: =Q22/$U$5 -> -91472.127
D23: 02.3 Comissões Mesa | E23: =CNS!B19+CRR!B18 -> -5749.27 | F23: =CNS!C19+CRR!C18 -> -5695.28 | G23: =CNS!D19+CRR!D18 -> -7461.4 | H23: =CNS!E19+CRR!E18 -> -5965.22 | I23: =CNS!F19+CRR!F18 -> -8479.87 | J23: =CNS!G19+CRR!G18 -> -6239.61 | K23: =CNS!H19+CRR!H18 -> -6458.99 | L23: =CNS!I19+CRR!I18 -> 0 | ... P23: =CNS!M19+CRR!M18 -> 0 | Q23: =SUM(E23:P23) -> -46049.64 | R23: =Q23/$Q$7 -> -0.023417429 | T23: 02.3 Comissões Mesa | U23: =Q23/$U$5 -> -6578.52
D24: 02.4 Descontos Incondicionais | E24: =CNS!B20+CRR!B19 -> 0 | F24: =CNS!C20+CRR!C19 -> -2730 | G24: =CNS!D20+CRR!D19 -> -420 | H24: =CNS!E20+CRR!E19 -> -1880.43 | I24: =CNS!F20+CRR!F19 -> -840 | J24: =CNS!G20+CRR!G19 -> 0 | K24: =CNS!H20+CRR!H19 -> 0 | L24: =CNS!I20+CRR!I19 -> 0 | ... P24: =CNS!M20+CRR!M19 -> 0 | Q24: =SUM(E24:P24) -> -5870.43 | R24: =Q24/$Q$7 -> -0.0029852649 | T24: 02.4 Descontos Incondicionais | U24: =Q24/$U$5 -> -838.63286
D25: 02.5 Devoluções de Vendas | E25: =CNS!B21+CRR!B20 -> -1163.72 | F25: =CNS!C21+CRR!C20 -> -1319.61 | G25: =CNS!D21+CRR!D20 -> -3923.62 | H25: =CNS!E21+CRR!E20 -> -1950.63 | I25: =CNS!F21+CRR!F20 -> -3298.79 | J25: =CNS!G21+CRR!G20 -> -1471.97 | K25: =CNS!H21+CRR!H20 -> -55.4 | L25: =CNS!I21+CRR!I20 -> 0 | ... P25: =CNS!M21+CRR!M20 -> 0 | Q25: =SUM(E25:P25) -> -13183.74 | R25: =Q25/$Q$7 -> -0.0067042715 | T25: 02.5 Devoluções de Vendas | U25: =Q25/$U$5 -> -1883.3914
D26: 02.6 Comissões Parceiros | E26: =CNS!B22+CRR!B21 -> -938.43 | F26: =CNS!C22+CRR!C21 -> -667.55 | G26: =CNS!D22+CRR!D21 -> -763.95 | H26: =CNS!E22+CRR!E21 -> -1072.24 | I26: =CNS!F22+CRR!F21 -> -930.88 | J26: =CNS!G22+CRR!G21 -> -306.22 | K26: =CNS!H22+CRR!H21 -> -1886.42 | L26: =CNS!I22+CRR!I21 -> 0 | ... P26: =CNS!M22+CRR!M21 -> 0 | Q26: =SUM(E26:P26) -> -6565.69 | R26: =Q26/$Q$7 -> -0.0033388226 | T26: 02.6 Comissões Parceiros | U26: =Q26/$U$5 -> -937.95571
D27: 02T Receita Líquida de Vendas | E27: =CNS!B23+CRR!B22 -> 83627.28 | F27: =CNS!C23+CRR!C22 -> 158675.15 | G27: =CNS!D23+CRR!D22 -> 134614.91 | H27: =CNS!E23+CRR!E22 -> 70306.19 | I27: =CNS!F23+CRR!F22 -> 148608.47 | J27: =CNS!G23+CRR!G22 -> 173501.15 | K27: =CNS!H23+CRR!H22 -> 85333.45 | L27: =CNS!I23+CRR!I22 -> 0 | ... P27: =CNS!M23+CRR!M22 -> 0 | Q27: =SUM(E27:P27) -> 854666.6 | R27: =Q27/$Q$7 -> 0.43461999 | T27: 02T Receita Líquida de Vendas | U27: =Q27/$U$5 -> 122095.23
D28: 03 Custos Operacionais | E28: =CNS!B24+CRR!B23 -> -64960.26 | F28: =CNS!C24+CRR!C23 -> -61297.63 | G28: =CNS!D24+CRR!D23 -> -67942.22 | H28: =CNS!E24+CRR!E23 -> -64575.13 | I28: =CNS!F24+CRR!F23 -> -81372.89 | J28: =CNS!G24+CRR!G23 -> -66612.71 | K28: =CNS!H24+CRR!H23 -> -59682.89 | L28: =CNS!I24+CRR!I23 -> 0 | ... P28: =CNS!M24+CRR!M23 -> 0 | Q28: =SUM(E28:P28) -> -466443.73 | R28: =Q28/$Q$7 -> -0.23719866 | T28: 03 Custos Operacionais | U28: =Q28/$U$5 -> -66634.819
D29: 03.1 Salários e Encargos | E29: =CNS!B25+CRR!B24 -> -25426.15 | F29: =CNS!C25+CRR!C24 -> -32678.58 | G29: =CNS!D25+CRR!D24 -> -28556.64 | H29: =CNS!E25+CRR!E24 -> -28209.13 | I29: =CNS!F25+CRR!F24 -> -33000.23 | J29: =CNS!G25+CRR!G24 -> -34300.75 | K29: =CNS!H25+CRR!H24 -> -28209.14 | L29: =CNS!I25+CRR!I24 -> 0 | ... P29: =CNS!M25+CRR!M24 -> 0 | Q29: =SUM(E29:P29) -> -210380.62 | R29: =Q29/$Q$7 -> -0.10698397 | T29: 03.1 Salários e Encargos | U29: =Q29/$U$5 -> -30054.374
D30: 03.2 Sistemas | E30: =CNS!B26+CRR!B25 -> -15523.46 | F30: =CNS!C26+CRR!C25 -> -9519.05 | G30: =CNS!D26+CRR!D25 -> -13097.35 | H30: =CNS!E26+CRR!E25 -> -10678.38 | I30: =CNS!F26+CRR!F25 -> -9918.7 | J30: =CNS!G26+CRR!G25 -> -9939.96 | K30: =CNS!H26+CRR!H25 -> -10299.93 | L30: =CNS!I26+CRR!I25 -> 0 | ... P30: =CNS!M26+CRR!M25 -> 0 | Q30: =SUM(E30:P30) -> -78976.83 | R30: =Q30/$Q$7 -> -0.040161753 | T30: 03.2 Sistemas | U30: =Q30/$U$5 -> -11282.404
D31: 03.3 Custo Tesouro mato grosso | E31: =CNS!B27+CRR!B26 -> -21367.88 | F31: =CNS!C27+CRR!C26 -> -19100 | G31: =CNS!D27+CRR!D26 -> -26235.23 | H31: =CNS!E27+CRR!E26 -> -25581.62 | I31: =CNS!F27+CRR!F26 -> -32735.46 | J31: =CNS!G27+CRR!G26 -> -22372 | K31: =CNS!H27+CRR!H26 -> -21173.82 | L31: =CNS!I27+CRR!I26 -> 0 | ... P31: =CNS!M27+CRR!M26 -> 0 | Q31: =SUM(E31:P31) -> -168566.01 | R31: =Q31/$Q$7 -> -0.08572016 | T31: 03.3 Custo Tesouro mato grosso | U31: =Q31/$U$5 -> -24080.859
... D45: 04.9 Veículos | E45: =CNS!B41+CRR!B40 -> 0 | F45: =CNS!C41+CRR!C40 -> 0 | G45: =CNS!D41+CRR!D40 -> 0 | H45: =CNS!E41+CRR!E40 -> 0 | I45: =CNS!F41+CRR!F40 -> 0 | J45: =CNS!G41+CRR!G40 -> 0 | K45: =CNS!H41+CRR!H40 -> 0 | L45: =CNS!I41+CRR!I40 -> 0 | ... P45: =CNS!M41+CRR!M40 -> 0 | Q45: =SUM(E45:P45) -> 0 | R45: =Q45/$Q$7 -> 0 | T45: 04.9 Veículos | U45: =Q45/$U$5 -> 0
D46: 04T Lucro / Prejuízo Operacional | E46: =CNS!B42+CRR!B41 -> -4814.48 | F46: =CNS!C42+CRR!C41 -> 73205.27 | G46: =CNS!D42+CRR!D41 -> 42036.29 | H46: =CNS!E42+CRR!E41 -> -15400.71 | I46: =CNS!F42+CRR!F41 -> 46543.06 | J46: =CNS!G42+CRR!G41 -> 86619.88 | K46: =CNS!H42+CRR!H41 -> -4722.47 | L46: =CNS!I42+CRR!I41 -> 0 | ... P46: =CNS!M42+CRR!M41 -> 0 | Q46: =SUM(E46:P46) -> 223466.84 | R46: =Q46/$Q$7 -> 0.11363865 | S46: =Q46/$Q$27 -> 0.26146668 | T46: 04T Lucro / Prejuízo Operacional | U46: =Q46/$U$5 -> 31923.834
D47: 05 Receitas e Despesas Financeiras | E47: =CNS!B43+CRR!B42 -> -1262.86 | F47: =CNS!C43+CRR!C42 -> -973.2 | G47: =CNS!D43+CRR!D42 -> -337.75 | H47: =CNS!E43+CRR!E42 -> -751.96 | I47: =CNS!F43+CRR!F42 -> 271.08 | J47: =CNS!G43+CRR!G42 -> -3516.44 | K47: =CNS!H43+CRR!H42 -> -129.72 | L47: =CNS!I43+CRR!I42 -> 0 | ... P47: =CNS!M43+CRR!M42 -> 0 | Q47: =SUM(E47:P47) -> -6700.85 | R47: =Q47/$Q$7 -> -0.0034075549 | T47: 05 Receitas e Despesas Financeiras | U47: =Q47/$U$5 -> -957.26429
D48: 06 Outras Receitas e Despesas Não Operacionais | E48: =CNS!B44+CRR!B43 -> 8.63 | F48: =CNS!C44+CRR!C43 -> 1.89 | G48: =CNS!D44+CRR!D43 -> 0.6 | H48: =CNS!E44+CRR!E43 -> 3.45 | I48: =CNS!F44+CRR!F43 -> 5.19 | J48: =CNS!G44+CRR!G43 -> 0 | K48: =CNS!H44+CRR!H43 -> -50 | L48: =CNS!I44+CRR!I43 -> 0 | ... P48: =CNS!M44+CRR!M43 -> 0 | Q48: =SUM(E48:P48) -> -30.24 | R48: =Q48/$Q$7 -> -1.5377819e-05 | T48: 06 Outras Receitas e Despesas Não Operacionais | U48: =Q48/$U$5 -> -4.32
D49: 06T Lucro / Prejuízo Líquido | E49: =CNS!B45+CRR!B44 -> -6068.71 | F49: =CNS!C45+CRR!C44 -> 72233.96 | G49: =CNS!D45+CRR!D44 -> 41699.14 | H49: =CNS!E45+CRR!E44 -> -16149.22 | I49: =CNS!F45+CRR!F44 -> 46819.33 | J49: =CNS!G45+CRR!G44 -> 83103.44 | K49: =CNS!H45+CRR!H44 -> -4902.19 | L49: =CNS!I45+CRR!I44 -> 0 | ... P49: =CNS!M45+CRR!M44 -> 0 | Q49: =SUM(E49:P49) -> 216735.75 | R49: =Q49/$Q$7 -> 0.11021571 | S49: =Q49/$Q$27 -> 0.25359099 | T49: 06T Lucro / Prejuízo Líquido | U49: =Q49/$U$5 -> 30962.25
D50: 07 Despesas com Investimentos e Empréstimos | E50: =CNS!B46+CRR!B45 -> -10236.57 | F50: =CNS!C46+CRR!C45 -> -10119.25 | G50: =CNS!D46+CRR!D45 -> -8739.58 | H50: =CNS!E46+CRR!E45 -> -10636.86 | I50: =CNS!F46+CRR!F45 -> -9270.03 | J50: =CNS!G46+CRR!G45 -> -9126.12 | K50: =CNS!H46+CRR!H45 -> -9386.01 | L50: =CNS!I46+CRR!I45 -> 0 | ... P50: =CNS!M46+CRR!M45 -> 0 | Q50: =SUM(E50:P50) -> -67514.42 | R50: =Q50/$Q$7 -> -0.034332822 | T50: 07 Despesas com Investimentos e Empréstimos | U50: =Q50/$U$5 -> -9644.9171
D51: 07.1 Investimentos em Imobilizado | E51: =CNS!B47+CRR!B46 -> 0 | F51: =CNS!C47+CRR!C46 -> -278.09 | G51: =CNS!D47+CRR!D46 -> 0 | H51: =CNS!E47+CRR!E46 -> -558.89 | I51: =CNS!F47+CRR!F46 -> 0 | J51: =CNS!G47+CRR!G46 -> 0 | K51: =CNS!H47+CRR!H46 -> 0 | L51: =CNS!I47+CRR!I46 -> 0 | ... P51: =CNS!M47+CRR!M46 -> 0 | Q51: =SUM(E51:P51) -> -836.98 | R51: =Q51/$Q$7 -> -0.0004256259 | T51: 07.1 Investimentos em Imobilizado | U51: =Q51/$U$5 -> -119.56857
D52: 07.2 Empréstimos e Dívidas | E52: =CNS!B48+CRR!B47 -> -10236.57 | F52: =CNS!C48+CRR!C47 -> -9841.16 | G52: =CNS!D48+CRR!D47 -> -8739.58 | H52: =CNS!E48+CRR!E47 -> -10077.97 | I52: =CNS!F48+CRR!F47 -> -9270.03 | J52: =CNS!G48+CRR!G47 -> -9126.12 | K52: =CNS!H48+CRR!H47 -> -9386.01 | L52: =CNS!I48+CRR!I47 -> 0 | ... P52: =CNS!M48+CRR!M47 -> 0 | Q52: =SUM(E52:P52) -> -66677.44 | R52: =Q52/$Q$7 -> -0.033907197 | T52: 07.2 Empréstimos e Dívidas | U52: =Q52/$U$5 -> -9525.3486
D53: 07T Lucro / Prejuízo Final | E53: =CNS!B49+CRR!B48 -> -16305.28 | F53: =CNS!C49+CRR!C48 -> 62114.71 | G53: =CNS!D49+CRR!D48 -> 32959.56 | H53: =CNS!E49+CRR!E48 -> -26786.08 | I53: =CNS!F49+CRR!F48 -> 37549.3 | J53: =CNS!G49+CRR!G48 -> 73977.32 | K53: =CNS!H49+CRR!H48 -> -14288.2 | L53: =CNS!I49+CRR!I48 -> 0 | ... P53: =CNS!M49+CRR!M48 -> 0 | Q53: =SUM(E53:P53) -> 149221.33 | R53: =Q53/$Q$7 -> 0.075882892 | S53: =Q53/$Q$27 -> 0.17459595 | T53: 07T Lucro / Prejuízo Final | U53: =Q53/$U$5 -> 21317.333
D58: EBITDA | E58: =E46+(-E21) -> 96700.12 | F58: =F46+(-F21) -> 97237.61 | G58: =G46+(-G21) -> 69380.73 | H58: =H46+(-H21) -> 74481.45 | I58: =I46+(-I21) -> 69807.3 | J58: =J46+(-J21) -> 111794.45 | K58: =K46+(-K21) -> 103892.87 | L58: =L46+(-L21) -> 0 | ... Q58: =Q46+(-Q21) -> 623294.53
D59: Caixa | E59: =IF(E7>0,Caixa!F6,0) -> 328679.42 | F59: =IF(F7>0,Caixa!G6,0) -> 326651.91 | G59: =IF(G7>0,Caixa!H6,0) -> 359161.59 | H59: =IF(H7>0,Caixa!I6,0) -> 358806.96 | I59: =IF(I7>0,Caixa!J6,0) -> 423235.48 | J59: =IF(J7>0,Caixa!K6,0) -> 430815.65 | K59: =IF(K7>0,Caixa!L6,0) -> 358819.06 | L59: =IF(L7>0,Caixa!M6,0) -> 0 | ... P59: =IF(P7>0,Caixa!Q6,0) -> 0
...

Sheet Caixa
T4: Distribuição
D5: CNPJ | E5: dez/25 | F5: 46023 | G5: fev/26 | H5: 46082 | I5: 46113 | J5: 46143 | K5: 46174 | L5: jul/26 | M5: ago/26 | N5: set/26 | O5: out/26 | P5: nov/26 | Q5: dez/26 | R5: Caixa final
D6: Caixa | E6: =E7+E10+E13+E16 -> 503909.51 | F6: =F7+F10+F13+F16 -> 328679.42 | G6: =G7+G10+G13+G16 -> 326651.91 | H6: =H7+H10+H13+H16 -> 359161.59 | I6: =I7+I10+I13+I16 -> 358806.96 | J6: =J7+J10+J13+J16 -> 423235.48 | K6: =K7+K10+K13+K16 -> 430815.65 | L6: =L7+L10+L13+L16 -> 358819.06 | ... Q6: =Q7+Q10+Q13+Q16 -> 0 | R6: =Q6 -> 0 | T6: Caixa final | U6: =R6 -> 0
D7: 1. BTG | E7: =E8+E9 -> 357656.17 | F7: =F8+F9 -> 224733.63 | G7: =G8+G9 -> 153902.69 | H7: =H8+H9 -> 228703.26 | I7: =I8+I9 -> 275711.18 | J7: =J8+J9 -> 307601.17 | K7: =K8+K9 -> 238663.08 | L7: =L8+L9 -> 252485.61 | ... Q7: =Q8+Q9 -> 0 | T7: -> Caixa | U7: 0
D8: 1.1 Investimentos | E8: 119132.9 | F8: 173160.08 | G8: =117727.34 -> 117727.34 | H8: 225718.41 | I8: =226743.76+971 -> 227714.76 | J8: =15000+254766.64 -> 269766.64 | K8: 148542.94 | L8: =252449.43 -> 252449.43 | T8: Bônus | U8: 0
D9: 1.2 Conta | E9: 238523.27 | F9: 51573.55 | G9: 36175.35 | H9: 2984.85 | I9: 47996.42 | J9: 37834.53 | K9: 90120.14 | L9: 36.18 | T9: Distribuição | U9: =U13 -> 59688.532
D10: 2. Consultoria | E10: =E11+E12 -> 102101.99 | F10: =F11+F12 -> 65399.48 | G10: =G11+G12 -> 137635.28 | H10: =H11+H12 -> 89865.77 | I10: =I11+I12 -> 49977.98 | J10: =J11+J12 -> 75090.4 | K10: =K11+K12 -> 163543.77 | L10: =L11+L12 -> 72044.26 | ... Q10: =Q11+Q12 -> 0 | T10: Saldo | U10: =U6-U8-U9 -> -59688.532
D11: 2.1 Investimentos | E11: 95400 | F11: 56600 | G11: 85600 | H11: 86880.92 | I11: 49432.66 | J11: 70999.62 | K11: 71750.61 | L11: 39676.26
D12: 2.2 Conta | E12: 6701.99 | F12: 8799.48 | G12: 52035.28 | H12: 2984.85 | I12: 545.32 | J12: 4090.78 | K12: 91793.16 | L12: 32368 | T12: Lucro Final | U12: =Consolidated!Q53 -> 149221.33
D13: 3. Corretora | E13: =E14+E15 -> 44151.35 | F13: =F14+F15 -> 38546.31 | G13: =G14+G15 -> 35113.94 | H13: =H14+H15 -> 40592.56 | I13: =I14+I15 -> 33117.8 | J13: =J14+J15 -> 40543.91 | K13: =K14+K15 -> 28608.8 | L13: =L14+L15 -> 34289.19 | ... Q13: =Q14+Q15 -> 0 | T13: 0.4 | U13: =U12*T13 -> 59688.532
D14: 3.1 Investimentos | E14: 29000 | F14: 23500 | G14: 17500 | H14: 27378.48 | I14: 18567.39 | J14: 29948.48 | K14: 10714.04 | L14: 10844.25 | T14: Distribuição | U14: =U9/Consolidated!Q53 -> 0.4
D15: 3.2 Conta | E15: 15151.35 | F15: 15046.31 | G15: 17613.94 | H15: 13214.08 | I15: 14550.41 | J15: 10595.43 | K15: 17894.76 | L15: 23444.94
D16: 4. Holding | E16: =E17+E18 -> 0 | F16: =F17+F18 -> 0 | G16: =G17+G18 -> 0 | H16: =H17+H18 -> 0 | I16: =I17+I18 -> 0 | J16: =J17+J18 -> 0 | K16: =K17+K18 -> 0 | L16: =L17+L18 -> 0 | ... Q16: =Q17+Q18 -> 0
D17: 4.1 Investimentos
D18: 4.2 Conta
D19: Δ Caixa | F19: =F6-E6 -> -175230.09 | G19: =G6-F6 -> -2027.51 | H19: =H6-G6 -> 32509.68 | I19: =IF(I6>0,I6-H6,0) -> -354.63 | J19: =IF(J6>0,J6-I6,0) -> 64428.52 | K19: =IF(K6>0,K6-J6,0) -> 7580.17 | L19: =IF(L6>0,L6-K6,0) -> -71996.59 | M19: =IF(M6>0,M6-L6,0) -> 0 | N19: =IF(N6>0,N6-M6,0) -> 0 | O19: =IF(O6>0,O6-N6,0) -> 0 | P19: =IF(P6>0,P6-O6,0) -> 0 | Q19: =IF(Q6>0,Q6-P6,0) -> 0
A42: Sim | D42: Check | F42: Meta | H42: =SUM(H43:H57) -> 30000
A43: Não | D43: Não | F43: Gaioso | G43: 15000 | H43: =IF(D43=$A$42,G43,0) -> 0
D44: Sim | F44: Augusto | G44: 15000 | H44: =IF(D44=$A$42,G44,0) -> 15000
D45: Não | F45: Sidney | G45: 15000 | H45: =IF(D45=$A$42,G45,0) -> 0
D46: Sim | F46: Lamour (+R) | G46: 15000 | H46: =IF(D46=$A$42,G46,0) -> 15000
D47: Não | F47: Pedro | G47: 15000 | H47: =IF(D47=$A$42,G47,0) -> 0
D48: Não | F48: Cris | G48: 15000 | H48: =IF(D48=$A$42,G48,0) -> 0
D49: Não | F49: Bruno | G49: 15000 | H49: =IF(D49=$A$42,G49,0) -> 0
D50: Não | F50: Mario | H50: =IF(D50=$A$42,G50,0) -> 0
D51: Não | F51: Elias | H51: =IF(D51=$A$42,G51,0) -> 0
D52: Não | F52: Igor | H52: =IF(D52=$A$42,G52,0) -> 0
D53: Não | F53: Nhat | H53: =IF(D53=$A$42,G53,0) -> 0
D54: Não | F54: Samuel | H54: =IF(D54=$A$42,G54,0) -> 0
D55: Não | F55: Bianka | H55: =IF(D55=$A$42,G55,0) -> 0
D56: Não | F56: Noemy | H56: =IF(D56=$A$42,G56,0) -> 0
D57: Não | F57: Vale | H57: =IF(D57=$A$42,G57,0) -> 0
D61: Lucro | G61: =I6 -> 358806.96 | H61: Total
D62: Gaioso | E62: 0.2847 | G62: =$G$61*E62 -> 102152.34 | H62: =G62+H43 -> 102152.34
D63: Augusto | E63: 0.2847 | G63: =$G$61*E63 -> 102152.34 | H63: =G63+H44 -> 117152.34
D64: Sidney | E64: 0.2847 | G64: =$G$61*E64 -> 102152.34 | H64: =G64+H45 -> 102152.34
D65: Lamour | E65: 0.0657 | G65: =$G$61*E65 -> 23573.617 | H65: =G65+H46 -> 38573.617
D66: Pedro | E66: 0.05 | G66: =$G$61*E66 -> 17940.348 | H66: =G66+H47 -> 17940.348
D67: Igor | E67: 0.03 | G67: =$G$61*E67 -> 10764.209 | H67: =G67+H52 -> 10764.209
D68: Cris | E68: 0.0001 | G68: =$G$61*E68 -> 35.880696 | H68: =G68+H48 -> 35.880696
...

Sheet Orçamento 2026
B1: ORÇAMENTO 2026 – DRE CONSOLIDADA (Grupo CVM + SUSEP)
B2: Premissas: AuM × ROA médio | Custos: IPCA 5,5% a.a. | Realizado: alimentado automaticamente da aba Consolidated
B4: PARÂMETROS E PREMISSAS (azul = entrada manual | preto = calculado automaticamente)
B5: AuM Alvo Dez/26 (R$) | C5: =J6 -> 280000000 | D5: Meta de AuM para Dez/26 – EDITÁVEL | I5: Aum0 | J5: 300000000 | K5: ROA | L5: 0.010918698 | N5: Consultoria | O5: 0.84359677 | T5: Consultoria | U5: Corretora
B6: ROA Médio Mensal (% a.m.) | C6: =(1+L5)^(1/12)-1 -> 0.00090536954 | D6: Calculado automaticamente – Jan–Abr/26 | I6: Meta | J6: 280000000 | K6: g | L6: 0 | N6: Corretora | O6: 0.15640323 | S6: Presunção | T6: 0.32 | U6: 0.32
B7: IPCA Anual 2026 | C7: 0.055 | D7: Taxa IPCA projetada – EDITÁVEL | I7: Cap | J7: =J6-J5 -> -20000000 | S7: IRPJ + CSLL | T7: 0.15 | U7: 0.15
B8: IPCA Mensal (composto) | C8: =(1+C7)^(1/12)-1 -> 0.0044716989 | D8: Calculado a partir do IPCA anual | I8: Cap mensal | J8: =J7/12 -> -1666666.7 | S8: Add IRPJ - 240k | T8: -0.1 | U8: 0.1
B9: IR Trimestral | C9: -0.06 | S9: CSLL | T9: 0.09 | U9: 0.068 | V9: =(T9*$O$5)+(U9*$O$6) -> 0.086559129
B10: % Impostos s/ Receita Bruta | C10: -0.14 | I10: Impostos sobre Receita | S10: PIS/COFINS | T10: 0.0365 | U10: 0.0365 | V10: =(T10*$O$5)+(U10*$O$6) -> 0.0365
B11: % Comissões s/ Receita Bruta | C11: -0.43 | I11: PIS | J11: -0.0065 | S11: ISS | T11: 0.05 | U11: 0.05 | V11: =(T11*$O$5)+(U11*$O$6) -> 0.05
B12: Descontos Incondicionais (méd. mensal) | C12: =AVERAGE(Consolidated!E24:H24) -> -1257.6075 | D12: Média Jan–Abr/26 | I12: COFINS | J12: -0.03 | S12: MÉDIA | T12: 18,5 - 19 | U12: 0.16
B13: Devoluções de Vendas (méd. mensal) | C13: 0 | D13: Média Jan–Abr/26 | I13: ISS | J13: -0.05
B14: Base Custos Operacionais (méd.) | C14: =AVERAGE(Consolidated!E28:H28) -> -64693.81 | D14: Média Jan–Abr/26 – IPCA composto mês a mês | J14: =SUM(J11:J13) -> -0.0865 | S14: Sidney | T14: 46360714 | U14: 29004.77
B15: Base Despesas Operacionais (méd.) | C15: =AVERAGE(Consolidated!E35:H35) -> -23355.48 | D15: Média Jan–Abr/26 – IPCA composto mês a mês | I15: Impostos sobre Presunção | K15: Excedente | L15: -0.1 | S15: Pedro | T15: 19600204 | U15: 16584.42
B16: Base Desp. Financeiras Líq. (méd.) | C16: =-0.4% -> -0.004 | D16: Média Jan–Abr/26 | I16: IRPJ | J16: -0.15 | S16: Total | T16: =T14+T15 -> 65960919 | U16: =U14+U15 -> 45589.19
B17: Base Desp. Invest./Empréstimos (méd.) | C17: -0.039277297 | D17: Média Jan–Abr/26 – IPCA composto mês a mês | I17: CSLL | J17: -0.086559129
B18: Base Outras Rec./Desp. N.Op. (méd.) | C18: 0 | D18: Média Jan–Abr/26 (valor imaterial) | J18: =J16+J17 -> -0.23655913
B19: ROA Consultoria | C19: 0.0005983766
B20: ROA Planejamento | C20: 4.1748034e-05 | S20: *Jan-Abril com números projetados
B21: RPPS | C21: 21495.8
B22: ROA Corretora | C22: 0.00013013201
B23: Mato grosso | C23: 34000
B25: TRAJETÓRIA DE AuM (Jan–Abr = realizados da aba Consolidado | Mai–Dez = interpolação linear até meta)
B26: AuM (R$) | C26: Jan/26 | D26: Fev/26 | E26: Mar/26 | F26: Abr/26 | G26: Mai/26 | H26: Jun/26 | I26: Jul/26 | J26: Ago/26 | K26: Set/26 | L26: Out/26 | M26: Nov/26 | N26: Dez/26 | O26: Total 2026
B27: AuM Projetado (R$) | C27: =Consolidated!E4 -> 290504767 | D27: =Consolidated!F4 -> 304511145 | E27: =Consolidated!G4 -> 309415143 | F27: =Consolidated!H4 -> 311856596 | G27: =F27*(1+$L$6) -> 311856596 | H27: =G27-T15 -> 2.9225639e+08 | I27: =H27*(1+$L$6) -> 2.9225639e+08 | J27: =I27-T14 -> 2.4589568e+08 | K27: =J27*(1+$L$6) -> 2.4589568e+08 | L27: =K27*(1+$L$6) -> 2.4589568e+08 | M27: =L27*(1+$L$6) -> 2.4589568e+08 | N27: =M27*(1+$L$6) -> 2.4589568e+08 | O27: =N27 -> 2.4589568e+08
B29: DRE ORÇADA 2026
B30: Categoria | C30: Jan/26 | D30: Fev/26 | E30: Mar/26 | F30: Abr/26 | G30: Mai/26 | H30: Jun/26 | I30: Jul/26 | J30: Ago/26 | K30: Set/26 | L30: Out/26 | M30: Nov/26 | N30: Dez/26 | O30: Total 2026 | X30: YTD (maio)
B31: 01 Receitas Operacionais | C31: =SUM(C32:C36) -> 279259.03 | D31: =SUM(D32:D36) -> 290047.53 | E31: =SUM(E32:E36) -> 293824.87 | F31: =SUM(F32:F36) -> 261705.42 | G31: =SUM(G32:G36) -> 295705.42 | H31: =SUM(H32:H36) -> 275752.11 | I31: =SUM(I32:I36) -> 275752.11 | J31: =SUM(J32:J36) -> 238778.86 | ... N31: =SUM(N32:N36) -> 238778.86 | O31: =SUM(C31:N31) -> 3165940.8 | W31: 01 Receitas Operacionais | X31: =SUM(C31:G31) -> 1420542.3
B32: Consultoria | C32: =C27*$C$19 -> 173831.26 | D32: =D27*$C$19 -> 182212.34 | E32: =E27*$C$19 -> 185146.78 | F32: =F27*$C$19 -> 186607.69 | G32: =G27*$C$19 -> 186607.69 | H32: =G32-U15 -> 170023.27 | I32: =H32*(1+$L$6) -> 170023.27 | J32: =I32*(1+$L$6)-U14 -> 141018.5 | K32: =J32*(1+$L$6) -> 141018.5 | L32: =K32*(1+$L$6) -> 141018.5 | M32: =L32*(1+$L$6) -> 141018.5 | N32: =M32*(1+$L$6) -> 141018.5 | O32: =SUM(C32:N32) -> 1959544.8 | W32: Consultoria | X32: =SUM(C32:G32) -> 914405.76
B33: Planejamento | C33: =C27*$C$20 -> 12128.003 | D33: =D27*$C$20 -> 12712.742 | E33: =E27*$C$20 -> 12917.474 | F33: =F27*$C$20 -> 13019.4 | G33: =G27*$C$20 -> 13019.4 | H33: =H27*$C$20 -> 12201.13 | I33: =I27*$C$20 -> 12201.13 | J33: =J27*$C$20 -> 10265.661 | ... N33: =N27*$C$20 -> 10265.661 | O33: =SUM(C33:N33) -> 139527.58 | W33: Planejamento | X33: =SUM(C33:G33) -> 63797.019
B34: Mato Grosso | C34: =CNS!B11 -> 34000 | D34: =CNS!C11 -> 34000 | E34: =CNS!D11 -> 34000 | F34: =CNS!E11 -> 0,00 | G34: =$C$23 -> 34000 | H34: =$C$23 -> 34000 | I34: =$C$23 -> 34000 | J34: =$C$23 -> 34000 | K34: =$C$23 -> 34000 | L34: =$C$23 -> 34000 | M34: =$C$23 -> 34000 | N34: =$C$23 -> 34000 | O34: =SUM(C34:N34) -> 374000 | W34: Mato Grosso | X34: =SUM(C34:G34) -> 136000
B35: RPPS | C35: =$C$21 -> 21495.8 | D35: =$C$21 -> 21495.8 | E35: =$C$21 -> 21495.8 | F35: =$C$21 -> 21495.8 | G35: =$C$21 -> 21495.8 | H35: =$C$21 -> 21495.8 | I35: =$C$21 -> 21495.8 | J35: =$C$21 -> 21495.8 | ... N35: =$C$21 -> 21495.8 | O35: =SUM(C35:N35) -> 257949.6 | W35: RPPS | X35: =SUM(C35:G35) -> 107479
B36: Corretora | C36: =C27*$C$22 -> 37803.97 | D36: =D27*$C$22 -> 39626.649 | E36: =E27*$C$22 -> 40264.816 | F36: =F27*$C$22 -> 40582.527 | G36: =G27*$C$22 -> 40582.527 | H36: =H27*$C$22 -> 38031.913 | I36: =I27*$C$22 -> 38031.913 | J36: =J27*$C$22 -> 31998.9 | ... N36: =N27*$C$22 -> 31998.9 | O36: =SUM(C36:N36) -> 434918.81 | W36: Corretora | X36: =SUM(C36:G36) -> 198860.49
B37: Presunção | C37: =C31*$T$6 -> 89362.889 | D37: =D31*$T$6 -> 92815.211 | E37: =E31*$T$6 -> 94023.959 | F37: =F31*$T$6 -> 83745.733 | G37: =G31*$T$6 -> 94625.733 | H37: =H31*$T$6 -> 88240.676 | I37: =I31*$T$6 -> 88240.676 | J37: =J31*$T$6 -> 76409.235 | ... N37: =N31*$T$6 -> 76409.235 | O37: =SUM(C37:N37) -> 1013101.1
B38: 02 Deduções da Receita Bruta | C38: =SUM(C39:C43) -> -198990.4 | D38: =SUM(D39:D43) -> -142721.51 | E38: =SUM(E39:E43) -> -144874.59 | F38: =SUM(F39:F43) -> -192974.39 | G38: =SUM(G39:G43) -> -145946.5 | H38: =SUM(H39:H43) -> -134573.12 | I38: =SUM(I39:I43) -> -184562.89 | J38: =SUM(J39:J43) -> -113498.36 | ... N38: =SUM(N39:N43) -> -113498.36 | O38: =SUM(C38:N38) -> -1757333.8
B39: 02.1 Impostos Sobre Vendas | C39: =Consolidated!E21-'Orçamento 2026'!C40 -> -55400.75 | D39: =D31*$C$10 -> -40606.655 | E39: =E31*$C$10 -> -41135.482 | F39: =F31*$C$10 -> -36638.758 | G39: =G31*$C$10 -> -41398.758 | H39: =H31*$C$10 -> -38605.296 | I39: =I31*$C$10 -> -38605.296 | J39: =J31*$C$10 -> -33429.041 | K39: =K31*$C$10 -> -33429.041 | ... O39: =O31*$C$10 -> -443231.71
B40: 02. 1. 1 - IRPJ Trimestral | C40: -46113.85 | F40: =SUM(C31:E31)*$C$9 -> -51787.886 | I40: =SUM(F31:H31)*$C$9 -> -49989.777 | L40: =SUM(I31:K31)*$C$9 -> -45198.59 | O40: =SUM(C40:N40) -> -193090.1
B41: 02.2 Comissões Sobre Vendas | C41: =(C32+C33+C36)*$C$11 -> -96218.188 | D41: =(D32+D33+D36)*$C$11 -> -100857.25 | E41: =(E32+E33+E36)*$C$11 -> -102481.5 | F41: =(F32+F33+F36)*$C$11 -> -103290.14 | G41: =(G32+G33+G36)*$C$11 -> -103290.14 | H41: =(H32+H33+H36)*$C$11 -> -94710.214 | I41: =(I32+I33+I36)*$C$11 -> -94710.214 | J41: =(J32+J33+J36)*$C$11 -> -78811.716 | ... N41: =(N32+N33+N36)*$C$11 -> -78811.716 | O41: =SUM(C41:N41) -> -1089616.2
B42: 02.3 Descontos Incondicionais | C42: =$C$12 -> -1257.6075 | D42: =$C$12 -> -1257.6075 | E42: =$C$12 -> -1257.6075 | F42: =$C$12 -> -1257.6075 | G42: =$C$12 -> -1257.6075 | H42: =$C$12 -> -1257.6075 | I42: =$C$12 -> -1257.6075 | J42: =$C$12 -> -1257.6075 | ... N42: =$C$12 -> -1257.6075 | O42: =SUM(C42:N42) -> -15091.29
B43: 02.4 Devoluções de Vendas | C43: =$C$13 -> 0 | D43: =$C$13 -> 0 | E43: =$C$13 -> 0 | F43: =$C$13 -> 0 | G43: =$C$13 -> 0 | H43: =$C$13 -> 0 | I43: =$C$13 -> 0 | J43: =$C$13 -> 0 | ... N43: =$C$13 -> 0 | O43: =SUM(C43:N43) -> 0
...

Sheet Gráficos 2026
B1: GRÁFICOS – REAL × ORÇADO 2026

Sheet Projeção
D2: Realizado
D3: Projetado
E5: Realizado | F5: Realizado | G5: Realizado | H5: Realizado | I5: Realizado | J5: Realizado | K5: Realizado | L5: Projetado | M5: Projetado | N5: Projetado | O5: Projetado | P5: Projetado
D7: AuM | E7: =AuM!C76 -> 290504767 | F7: =AuM!C77 -> 304511145 | G7: =AuM!C78 -> 309415143 | H7: =AuM!C79 -> 311856596 | I7: =IF(I5=$D$2,Consolidated!I4,'Orçamento 2026'!G27) -> 312069591 | J7: =IF(J5=$D$2,Consolidated!J4,'Orçamento 2026'!H27) -> 295791970 | K7: =IF(K5=$D$2,Consolidated!K4,'Orçamento 2026'!I27) -> 254401486 | L7: =IF(L5=$D$2,Consolidated!L4,'Orçamento 2026'!J27) -> 2.4589568e+08 | M7: =IF(M5=$D$2,Consolidated!M4,'Orçamento 2026'!K27) -> 2.4589568e+08 | N7: =IF(N5=$D$2,Consolidated!N4,'Orçamento 2026'!L27) -> 2.4589568e+08 | O7: =IF(O5=$D$2,Consolidated!O4,'Orçamento 2026'!M27) -> 2.4589568e+08 | P7: =IF(P5=$D$2,Consolidated!P4,'Orçamento 2026'!N27) -> 2.4589568e+08 | Q7: Média | U7: Média
D8: ROA Anualizado | E8: =IF(E7>0,(E10/E7)*12,"") -> 0.011667028 | F8: =IF(F7>0,(F10/F7)*12,"") -> 0.011230968 | G8: =IF(G7>0,(G10/G7)*12,"") -> 0.010579819 | H8: =IF(H7>0,(H10/H7)*12,"") -> 0.010263203 | I8: =IF(I7>0,(I10/I7)*12,"") -> 0.010664336 | J8: =IF(J7>0,(J10/J7)*12,"") -> 0.012233917 | K8: =IF(K7>0,(K10/K7)*12,"") -> 0.013236672 | L8: =IF(L7>0,(L10/L7)*12,"") -> 0.011652691 | ... P8: =IF(P7>0,(P10/P7)*12,"") -> 0.011652691 | Q8: =AVERAGE(E8:P8) -> 0.011511616 | U8: 12
D9: Categoria | E9: Jan/2026 | F9: Fev/2026 | G9: Mar/2026 | H9: Abr/2026 | I9: 46143 | J9: 46174 | K9: 46204 | L9: 46235 | M9: 46266 | N9: 46296 | O9: 46327 | P9: 46357 | Q9: Total | U9: Total
D10: 01 Receitas Operacionais | E10: =CNS!B8+CRR!B8 -> 282443.93 | F10: =CNS!C8+CRR!C8 -> 284996.24 | G10: =CNS!D8+CRR!D8 -> 272796.35 | H10: =CNS!E8+CRR!E8 -> 266720.63 | I10: =IF(I5=$D$2,Consolidated!I7,SUM(I11:I21)) -> 277334.58 | J10: =IF(J5=$D$2,Consolidated!J7,SUM(J11:J21)) -> 301557.87 | K10: =IF(K5=$D$2,Consolidated!K7,SUM(K11:K21)) -> 280619.08 | L10: =IF(L5=$D$2,Consolidated!L7,SUM(L11:L21)) -> 238778.86 | M10: =IF(M5=$D$2,Consolidated!M7,SUM(M11:M21)) -> 238778.86 | N10: =IF(N5=$D$2,Consolidated!N7,SUM(N11:N21)) -> 238778.86 | O10: =IF(O5=$D$2,Consolidated!O7,SUM(O11:O21)) -> 238778.86 | P10: =IF(P5=$D$2,Consolidated!P7,SUM(P11:P21)) -> 238778.86 | Q10: =SUM(E10:P10) -> 3160363 | T10: 01 Receitas Operacionais | U10: =Q10/$U$8 -> 263363.58
D11: Consultoria | E11: =CNS!B9 -> 175809.2 | F11: =CNS!C9 -> 178265.28 | G11: =CNS!D9 -> 183175.54 | H11: =CNS!E9 -> 191954.82 | I11: =IF(I5=$D$2,CNS!F9,'Orçamento 2026'!G32) -> 192414.3 | J11: =IF(J5=$D$2,CNS!G9,'Orçamento 2026'!H32) -> 187551.84 | K11: =IF(K5=$D$2,CNS!H9,'Orçamento 2026'!I32) -> 175356.62 | L11: =IF(L5=$D$2,CNS!I9,'Orçamento 2026'!J32) -> 141018.5 | M11: =IF(M5=$D$2,CNS!J9,'Orçamento 2026'!K32) -> 141018.5 | N11: =IF(N5=$D$2,CNS!K9,'Orçamento 2026'!L32) -> 141018.5 | O11: =IF(O5=$D$2,CNS!L9,'Orçamento 2026'!M32) -> 141018.5 | P11: =IF(P5=$D$2,CNS!M9,'Orçamento 2026'!N32) -> 141018.5 | Q11: =SUM(E11:P11) -> 1989620.1 | R11: =Q11/$Q$10 -> 0.6295543 | T11: Consultoria | U11: =Q11/$U$8 -> 165801.67
D12: Planejamento | E12: =CNS!B10 -> 14700 | F12: =CNS!C10 -> 18900 | G12: =CNS!D10 -> 10400 | H12: =CNS!E10 -> 6500 | I12: =IF(I5=$D$2,CNS!F10,'Orçamento 2026'!G33) -> 6500 | J12: =IF(J5=$D$2,CNS!G10,'Orçamento 2026'!H33) -> 0,00 | K12: =IF(K5=$D$2,CNS!H10,'Orçamento 2026'!I33) -> 18270 | L12: =IF(L5=$D$2,CNS!I10,'Orçamento 2026'!J33) -> 10265.661 | M12: =IF(M5=$D$2,CNS!J10,'Orçamento 2026'!K33) -> 10265.661 | N12: =IF(N5=$D$2,CNS!K10,'Orçamento 2026'!L33) -> 10265.661 | O12: =IF(O5=$D$2,CNS!L10,'Orçamento 2026'!M33) -> 10265.661 | P12: =IF(P5=$D$2,CNS!M10,'Orçamento 2026'!N33) -> 10265.661 | Q12: =SUM(E12:P12) -> 126598.31 | R12: =Q12/$Q$10 -> 0.040058154 | T12: Planejamento | U12: =Q12/$U$8 -> 10549.859
D13: Tesouro Mato Grosso | E13: =CNS!B11 -> 34000 | F13: =CNS!C11 -> 34000 | G13: =CNS!D11 -> 34000 | H13: =CNS!E11 -> 0,00 | I13: =IF(I5=$D$2,CNS!F11,'Orçamento 2026'!G34) -> 34000 | J13: =IF(J5=$D$2,CNS!G11,'Orçamento 2026'!H34) -> 83700 | K13: =IF(K5=$D$2,CNS!H11,'Orçamento 2026'!I34) -> 34000 | L13: =IF(L5=$D$2,CNS!I11,'Orçamento 2026'!J34) -> 34000 | M13: =IF(M5=$D$2,CNS!J11,'Orçamento 2026'!K34) -> 34000 | N13: =IF(N5=$D$2,CNS!K11,'Orçamento 2026'!L34) -> 34000 | O13: =IF(O5=$D$2,CNS!L11,'Orçamento 2026'!M34) -> 34000 | P13: =IF(P5=$D$2,CNS!M11,'Orçamento 2026'!N34) -> 34000 | Q13: =SUM(E13:P13) -> 423700 | R13: =Q13/$Q$10 -> 0.13406688 | T13: Tesouro Mato Grosso | U13: =Q13/$U$8 -> 35308.333
D14: RPPS | E14: =CNS!B12 -> 15346 | F14: =CNS!C12 -> 18715.86 | G14: =CNS!D12 -> 0,00 | H14: =CNS!E12 -> 30425.54 | I14: =IF(I5=$D$2,CNS!F12,'Orçamento 2026'!G35) -> 0,00 | J14: =IF(J5=$D$2,CNS!G12,'Orçamento 2026'!H35) -> 6238.62 | K14: =IF(K5=$D$2,CNS!H12,'Orçamento 2026'!I35) -> 0,00 | L14: =IF(L5=$D$2,CNS!I12,'Orçamento 2026'!J35) -> 21495.8 | M14: =IF(M5=$D$2,CNS!J12,'Orçamento 2026'!K35) -> 21495.8 | N14: =IF(N5=$D$2,CNS!K12,'Orçamento 2026'!L35) -> 21495.8 | O14: =IF(O5=$D$2,CNS!L12,'Orçamento 2026'!M35) -> 21495.8 | P14: =IF(P5=$D$2,CNS!M12,'Orçamento 2026'!N35) -> 21495.8 | Q14: =SUM(E14:P14) -> 178205.02 | R14: =Q14/$Q$10 -> 0.056387517 | T14: RPPS | U14: =Q14/$U$8 -> 14850.418
D15: Consulta | E15: =CNS!B13 -> 0,00 | F15: =CNS!C13 -> 750 | G15: =CNS!D13 -> 600 | H15: =CNS!E13 -> 1200 | I15: =IF(I5=$D$2,CNS!F13,0) -> 0,00 | J15: =IF(J5=$D$2,CNS!G13,0) -> 0,00 | K15: =IF(K5=$D$2,CNS!H13,0) -> 0,00 | L15: =IF(L5=$D$2,CNS!I13,0) -> 0 | M15: =IF(M5=$D$2,CNS!J13,0) -> 0 | N15: =IF(N5=$D$2,CNS!K13,0) -> 0 | O15: =IF(O5=$D$2,CNS!L13,0) -> 0 | P15: =IF(P5=$D$2,CNS!M13,0) -> 0 | Q15: =SUM(E15:P15) -> 2550 | R15: =Q15/$Q$10 -> 0.00080686934 | T15: Consulta | U15: =Q15/$U$8 -> 212.5
D16: Valuation | E16: =CNS!B14 -> 0 | F16: =CNS!C14 -> 0,00 | G16: =CNS!D14 -> 0,00 | H16: =CNS!E14 -> 0,00 | I16: =IF(I5=$D$2,CNS!F14,0) -> 0,00 | J16: =IF(J5=$D$2,CNS!G14,0) -> 0,00 | K16: =IF(K5=$D$2,CNS!H14,0) -> 0,00 | L16: =IF(L5=$D$2,CNS!I14,0) -> 0 | M16: =IF(M5=$D$2,CNS!J14,0) -> 0 | N16: =IF(N5=$D$2,CNS!K14,0) -> 0 | O16: =IF(O5=$D$2,CNS!L14,0) -> 0 | P16: =IF(P5=$D$2,CNS!M14,0) -> 0 | Q16: =SUM(E16:P16) -> 0 | R16: =Q16/$Q$10 -> 0 | T16: Valuation | U16: =Q16/$U$8 -> 0
D17: Câmbio/Bancários | E17: =CRR!B9 -> 2129.24 | F17: =CRR!C9 -> 4080.01 | G17: =CRR!D9 -> 7882.59 | H17: =CRR!E9 -> 3358.51 | I17: =IF(I5=$D$2,CRR!F9,'Orçamento 2026'!G36) -> 4335.02 | J17: =IF(J5=$D$2,CRR!G9,'Orçamento 2026'!H36) -> 0,00 | K17: =IF(K5=$D$2,CRR!H9,'Orçamento 2026'!I36) -> 5592.59 | L17: =IF(L5=$D$2,CRR!I9,'Orçamento 2026'!J36) -> 31998.9 | M17: =IF(M5=$D$2,CRR!J9,'Orçamento 2026'!K36) -> 31998.9 | N17: =IF(N5=$D$2,CRR!K9,'Orçamento 2026'!L36) -> 31998.9 | O17: =IF(O5=$D$2,CRR!L9,'Orçamento 2026'!M36) -> 31998.9 | P17: =IF(P5=$D$2,CRR!M9,'Orçamento 2026'!N36) -> 31998.9 | Q17: =SUM(E17:P17) -> 187372.46 | R17: =Q17/$Q$10 -> 0.059288271 | T17: Câmbio/Bancários | U17: =Q17/$U$8 -> 15614.372
D18: Consórcio | E18: =CRR!B10 -> 11277.6 | F18: =CRR!C10 -> 11277.6 | G18: =CRR!D10 -> 11277.6 | H18: =CRR!E10 -> 11277.6 | I18: =IF(I5=$D$2,CRR!F10,0) -> 11277.6 | J18: =IF(J5=$D$2,CRR!G10,0) -> 0,00 | K18: =IF(K5=$D$2,CRR!H10,0) -> 17767.2 | L18: =IF(L5=$D$2,CRR!I10,0) -> 0 | M18: =IF(M5=$D$2,CRR!J10,0) -> 0 | N18: =IF(N5=$D$2,CRR!K10,0) -> 0 | O18: =IF(O5=$D$2,CRR!L10,0) -> 0 | P18: =IF(P5=$D$2,CRR!M10,0) -> 0 | Q18: =SUM(E18:P18) -> 74155.2 | R18: =Q18/$Q$10 -> 0.02346414 | T18: Consórcio | U18: =Q18/$U$8 -> 6179.6
D19: Previdência | E19: =CRR!B11 -> 4958.36 | F19: =CRR!C11 -> 4860.28 | G19: =CRR!D11 -> 6325.28 | H19: =CRR!E11 -> 5913.91 | I19: =IF(I5=$D$2,CRR!F11,0) -> 2187.12 | J19: =IF(J5=$D$2,CRR!G11,0) -> 3486.48 | K19: =IF(K5=$D$2,CRR!H11,0) -> 3208.11 | L19: =IF(L5=$D$2,CRR!I11,0) -> 0 | M19: =IF(M5=$D$2,CRR!J11,0) -> 0 | N19: =IF(N5=$D$2,CRR!K11,0) -> 0 | O19: =IF(O5=$D$2,CRR!L11,0) -> 0 | P19: =IF(P5=$D$2,CRR!M11,0) -> 0 | Q19: =SUM(E19:P19) -> 30939.54 | R19: =Q19/$Q$10 -> 0.0097898691 | T19: Previdência | U19: =Q19/$U$8 -> 2578.295
D20: Seguro de vida | E20: =CRR!B12 -> 20365.39 | F20: =CRR!C12 -> 11096.95 | G20: =CRR!D12 -> 13782.61 | H20: =CRR!E12 -> 11693.06 | I20: =IF(I5=$D$2,CRR!F12,0) -> 19858.71 | J20: =IF(J5=$D$2,CRR!G12,0) -> 16176.26 | K20: =IF(K5=$D$2,CRR!H12,0) -> 19179.52 | L20: =IF(L5=$D$2,CRR!I12,0) -> 0 | M20: =IF(M5=$D$2,CRR!J12,0) -> 0 | N20: =IF(N5=$D$2,CRR!K12,0) -> 0 | O20: =IF(O5=$D$2,CRR!L12,0) -> 0 | P20: =IF(P5=$D$2,CRR!M12,0) -> 0 | Q20: =SUM(E20:P20) -> 112152.5 | R20: =Q20/$Q$10 -> 0.035487221 | T20: Seguro de vida | U20: =Q20/$U$8 -> 9346.0417
D21: Outros Ramos | E21: =CRR!B13 -> 3858.14 | F21: =CRR!C13 -> 3050.26 | G21: =CRR!D13 -> 5352.73 | H21: =CRR!E13 -> 4397.19 | I21: =IF(I5=$D$2,CRR!F13,0) -> 6761.83 | J21: =IF(J5=$D$2,CRR!G13,0) -> 4404.67 | K21: =IF(K5=$D$2,CRR!H13,0) -> 7245.04 | L21: =IF(L5=$D$2,CRR!I13,0) -> 0 | M21: =IF(M5=$D$2,CRR!J13,0) -> 0 | N21: =IF(N5=$D$2,CRR!K13,0) -> 0 | O21: =IF(O5=$D$2,CRR!L13,0) -> 0 | P21: =IF(P5=$D$2,CRR!M13,0) -> 0 | Q21: =SUM(E21:P21) -> 35069.86 | R21: =Q21/$Q$10 -> 0.011096782 | T21: Outros Ramos | U21: =Q21/$U$8 -> 2922.4883
D22: 01T Receita Bruta de Vendas | Q22: =SUM(E22:P22) -> 0 | R22: =Q22/$Q$10 -> 0 | T22: 01T Receita Bruta de Vendas | U22: =Q22/$U$8 -> 0
D23: 02 Deduções da Receita Bruta | E23: =CNS!B16+CRR!B15 -> -198816.65 | F23: =CNS!C16+CRR!C15 -> -126321.09 | G23: =CNS!D16+CRR!D15 -> -138181.44 | H23: =CNS!E16+CRR!E15 -> -196414.44 | I23: =IF(I5=$D$2,Consolidated!I20,SUM(Projeção!I24:I29)) -> -128726.11 | J23: =IF(J5=$D$2,Consolidated!J20,SUM(Projeção!J24:J29)) -> -128056.72 | K23: =IF(K5=$D$2,Consolidated!K20,SUM(Projeção!K24:K29)) -> -195285.63 | L23: =IF(L5=$D$2,Consolidated!L20,SUM(Projeção!L24:L29)) -> -113498.36 | M23: =IF(M5=$D$2,Consolidated!M20,SUM(Projeção!M24:M29)) -> -113498.36 | N23: =IF(N5=$D$2,Consolidated!N20,SUM(Projeção!N24:N29)) -> -158696.95 | O23: =IF(O5=$D$2,Consolidated!O20,SUM(Projeção!O24:O29)) -> -113498.36 | P23: =IF(P5=$D$2,Consolidated!P20,SUM(Projeção!P24:P29)) -> -113498.36 | Q23: =SUM(E23:P23) -> -1724492.5 | R23: =Q23/$Q$10 -> -0.54566279 | T23: 02 Deduções da Receita Bruta | U23: =Q23/$U$8 -> -143707.71
D24: 02.1 Impostos Sobre Vendas | E24: =CNS!B17+CRR!B16 -> -101514.6 | F24: =CNS!C17+CRR!C16 -> -24032.34 | G24: =CNS!D17+CRR!D16 -> -27344.44 | H24: =CNS!E17+CRR!E16 -> -89882.16 | I24: =IF(I5=$D$2,Consolidated!I21,'Orçamento 2026'!G39+'Orçamento 2026'!G40) -> -23264.24 | J24: =IF(J5=$D$2,Consolidated!J21,'Orçamento 2026'!H39+'Orçamento 2026'!H40) -> -25174.57 | K24: =IF(K5=$D$2,Consolidated!K21,'Orçamento 2026'!I39+'Orçamento 2026'!I40) -> -108615.34 | L24: =IF(L5=$D$2,Consolidated!L21,'Orçamento 2026'!J39+'Orçamento 2026'!J40) -> -33429.041 | M24: =IF(M5=$D$2,Consolidated!M21,'Orçamento 2026'!K39+'Orçamento 2026'!K40) -> -33429.041 | N24: =IF(N5=$D$2,Consolidated!N21,'Orçamento 2026'!L39+'Orçamento 2026'!L40) -> -78627.631 | O24: =IF(O5=$D$2,Consolidated!O21,'Orçamento 2026'!M39+'Orçamento 2026'!M40) -> -33429.041 | P24: =IF(P5=$D$2,Consolidated!P21,'Orçamento 2026'!N39+'Orçamento 2026'!N40) -> -33429.041 | Q24: =SUM(E24:P24) -> -612171.48 | R24: =Q24/$Q$10 -> -0.1937029 | T24: 02.1 Impostos Sobre Vendas | U24: =Q24/$U$8 -> -51014.29
D25: 02.2 Comissões Consultores | E25: =CNS!B18+CRR!B17 -> -89450.63 | F25: =CNS!C18+CRR!C17 -> -91876.31 | G25: =CNS!D18+CRR!D17 -> -98268.03 | H25: =CNS!E18+CRR!E17 -> -95663.76 | I25: =IF(I5=$D$2,Consolidated!I22,'Orçamento 2026'!G41) -> -91912.33 | J25: =IF(J5=$D$2,Consolidated!J22,'Orçamento 2026'!H41) -> -94864.35 | K25: =IF(K5=$D$2,Consolidated!K22,'Orçamento 2026'!I41) -> -78269.48 | L25: =IF(L5=$D$2,Consolidated!L22,'Orçamento 2026'!J41) -> -78811.716 | M25: =IF(M5=$D$2,Consolidated!M22,'Orçamento 2026'!K41) -> -78811.716 | N25: =IF(N5=$D$2,Consolidated!N22,'Orçamento 2026'!L41) -> -78811.716 | O25: =IF(O5=$D$2,Consolidated!O22,'Orçamento 2026'!M41) -> -78811.716 | P25: =IF(P5=$D$2,Consolidated!P22,'Orçamento 2026'!N41) -> -78811.716 | Q25: =SUM(E25:P25) -> -1034363.5 | R25: =Q25/$Q$10 -> -0.32729262 | T25: 02.2 Comissões Consultores | U25: =Q25/$U$8 -> -86196.956
D26: 02.3 Comissões Mesa | E26: =CNS!B19+CRR!B18 -> -5749.27 | F26: =CNS!C19+CRR!C18 -> -5695.28 | G26: =CNS!D19+CRR!D18 -> -7461.4 | H26: =CNS!E19+CRR!E18 -> -5965.22 | I26: =IF(I5=$D$2,Consolidated!I23,0) -> -8479.87 | J26: =IF(J5=$D$2,Consolidated!J23,0) -> -6239.61 | K26: =IF(K5=$D$2,Consolidated!K23,0) -> -6458.99 | L26: =IF(L5=$D$2,Consolidated!L23,0) -> 0 | M26: =IF(M5=$D$2,Consolidated!M23,0) -> 0 | N26: =IF(N5=$D$2,Consolidated!N23,0) -> 0 | O26: =IF(O5=$D$2,Consolidated!O23,0) -> 0 | P26: =IF(P5=$D$2,Consolidated!P23,0) -> 0 | Q26: =SUM(E26:P26) -> -46049.64 | R26: =Q26/$Q$10 -> -0.014570997 | T26: 02.3 Comissões Mesa | U26: =Q26/$U$8 -> -3837.47
D27: 02.4 Descontos Incondicionais | E27: =CNS!B20+CRR!B19 -> 0 | F27: =CNS!C20+CRR!C19 -> -2730 | G27: =CNS!D20+CRR!D19 -> -420 | H27: =CNS!E20+CRR!E19 -> -1880.43 | I27: =IF(I5=$D$2,Consolidated!I24,'Orçamento 2026'!G42) -> -840 | J27: =IF(J5=$D$2,Consolidated!J24,'Orçamento 2026'!H42) -> 0 | K27: =IF(K5=$D$2,Consolidated!K24,'Orçamento 2026'!I42) -> 0 | L27: =IF(L5=$D$2,Consolidated!L24,'Orçamento 2026'!J42) -> -1257.6075 | M27: =IF(M5=$D$2,Consolidated!M24,'Orçamento 2026'!K42) -> -1257.6075 | N27: =IF(N5=$D$2,Consolidated!N24,'Orçamento 2026'!L42) -> -1257.6075 | O27: =IF(O5=$D$2,Consolidated!O24,'Orçamento 2026'!M42) -> -1257.6075 | P27: =IF(P5=$D$2,Consolidated!P24,'Orçamento 2026'!N42) -> -1257.6075 | Q27: =SUM(E27:P27) -> -12158.468 | R27: =Q27/$Q$10 -> -0.0038471744 | T27: 02.4 Descontos Incondicionais | U27: =Q27/$U$8 -> -1013.2056
D28: 02.5 Devoluções de Vendas | E28: =CNS!B21+CRR!B20 -> -1163.72 | F28: =CNS!C21+CRR!C20 -> -1319.61 | G28: =CNS!D21+CRR!D20 -> -3923.62 | H28: =CNS!E21+CRR!E20 -> -1950.63 | I28: =IF(I5=$D$2,Consolidated!I25,'Orçamento 2026'!G43) -> -3298.79 | J28: =CNS!G21+CRR!G20 -> -1471.97 | K28: =CNS!H21+CRR!H20 -> -55.4 | L28: =CNS!I21+CRR!I20 -> 0 | M28: =CNS!J21+CRR!J20 -> 0 | N28: =CNS!K21+CRR!K20 -> 0 | O28: =CNS!L21+CRR!L20 -> 0 | P28: =CNS!M21+CRR!M20 -> 0 | Q28: =SUM(E28:P28) -> -13183.74 | R28: =Q28/$Q$10 -> -0.0041715904 | T28: 02.5 Devoluções de Vendas | U28: =Q28/$U$8 -> -1098.645
D29: 02.6 Comissões Parceiros | E29: =CNS!B22+CRR!B21 -> -938.43 | F29: =CNS!C22+CRR!C21 -> -667.55 | G29: =CNS!D22+CRR!D21 -> -763.95 | H29: =CNS!E22+CRR!E21 -> -1072.24 | I29: =IF(I5=$D$2,Consolidated!I26,0) -> -930.88 | J29: =IF(J5=$D$2,Consolidated!J26,0) -> -306.22 | K29: =IF(K5=$D$2,Consolidated!K26,0) -> -1886.42 | L29: =IF(L5=$D$2,Consolidated!L26,0) -> 0 | M29: =IF(M5=$D$2,Consolidated!M26,0) -> 0 | N29: =IF(N5=$D$2,Consolidated!N26,0) -> 0 | O29: =IF(O5=$D$2,Consolidated!O26,0) -> 0 | P29: =IF(P5=$D$2,Consolidated!P26,0) -> 0 | Q29: =SUM(E29:P29) -> -6565.69 | R29: =Q29/$Q$10 -> -0.0020775114 | T29: 02.6 Comissões Parceiros | U29: =Q29/$U$8 -> -547.14083
D30: 02T Receita Líquida de Vendas | E30: =CNS!B23+CRR!B22 -> 83627.28 | F30: =CNS!C23+CRR!C22 -> 158675.15 | G30: =CNS!D23+CRR!D22 -> 134614.91 | H30: =CNS!E23+CRR!E22 -> 70306.19 | I30: =I10+I23 -> 148608.47 | J30: =J10+J23 -> 173501.15 | K30: =K10+K23 -> 85333.45 | L30: =L10+L23 -> 125280.5 | M30: =M10+M23 -> 125280.5 | N30: =N10+N23 -> 80081.907 | O30: =O10+O23 -> 125280.5 | P30: =P10+P23 -> 125280.5 | Q30: =SUM(E30:P30) -> 1435870.5 | R30: =Q30/$Q$10 -> 0.45433721 | T30: 02T Receita Líquida de Vendas | U30: =Q30/$U$8 -> 119655.87
